2016-03-05 22:26:27,381 - softwarecenter.ui.gtk3.app - INFO - setting up proxy 'None'
2016-03-05 22:26:33,830 - softwarecenter.region - WARNING - failed to use geoclue: 'org.freedesktop.Geoclue.Error.notAvailable: Geoclue master client has no usable Address providers'
2016-03-05 22:26:34,585 - softwarecenter.backend.reviews - WARNING - Could not get usefulness from server, no username in config file
2016-03-05 22:26:34,617 - softwarecenter.plugin - INFO - activating plugin '<module 'webapps_activation' from '/usr/share/software-center/softwarecenter/plugins/webapps_activation.pyc'>'
2016-03-05 22:26:34,723 - softwarecenter.fixme - WARNING - logs to the root logger: '('/usr/lib/python2.7/dist-packages/gi/importer.py', 51, 'find_module')'
2016-03-05 22:26:34,723 - root - ERROR - Could not find any typelib for LaunchpadIntegration
2016-03-05 22:26:35,158 - softwarecenter.db.pkginfo_impl.aptcache - INFO - aptcache.open()
2016-03-05 22:26:48,516 - softwarecenter.backend.spawn_helper - WARNING - exit code 1 from helper for '['/usr/share/software-center/piston_generic_helper.py', '--datadir', '/usr/share/software-center/', 'SoftwareCenterAgentAPI', 'available_apps', '{"lang": "zh_CN", "series": "trusty", "arch": "amd64"}']'
2016-03-05 22:26:48,520 - softwarecenter.backend.spawn_helper - WARNING - got error from helper: 'WARNING:__main__:No JSON object could be decoded
'
2016-03-05 22:26:48,522 - softwarecenter.db.update - WARNING - update_from_software_center_agent: error: 'WARNING:__main__:No JSON object could be decoded\n'
2016-03-05 22:26:50,450 - softwarecenter.backend.spawn_helper - WARNING - exit code 1 from helper for '['/usr/share/software-center/piston_generic_helper.py', '--datadir', '/usr/share/software-center/', 'RatingsAndReviewsAPI', 'review_stats']'
2016-03-05 22:26:50,457 - softwarecenter.backend.spawn_helper - WARNING - got error from helper: 'WARNING:__main__:No JSON object could be decoded
'
2016-03-05 22:26:50,489 - softwarecenter.db.utils - INFO - software-center-agent finished with status 1
2016-03-05 22:26:50,496 - softwarecenter.backend.spawn_helper - WARNING - exit code 1 from helper for '['/usr/share/software-center/piston_generic_helper.py', '--datadir', '/usr/share/software-center/', 'SoftwareCenterAgentAPI', 'exhibits', '{"lang": "zh_CN", "series": "trusty"}']'
2016-03-05 22:26:50,498 - softwarecenter.backend.spawn_helper - WARNING - got error from helper: 'ERROR:__main__:urclient_apps
Traceback (most recent call last):
  File "/usr/share/software-center/piston_generic_helper.py", line 147, in <module>
    piston_reply = f(**kwargs)
  File "/usr/lib/python2.7/dist-packages/piston_mini_client/validators.py", line 49, in wrapper
    return func(*args, **kwargs)
  File "/usr/lib/python2.7/dist-packages/piston_mini_client/validators.py", line 49, in wrapper
    return func(*args, **kwargs)
  File "/usr/lib/python2.7/dist-packages/piston_mini_client/__init__.py", line 168, in wrapper
    body = func(self, *args, **kwargs)
  File "/usr/share/software-center/softwarecenter/backend/piston/scaclient_pristine.py", line 59, in exhibits
    return self._get(url)
  File "/usr/lib/python2.7/dist-packages/piston_mini_client/__init__.py", line 787, in _get
    extra_headers=extra_headers)
  File "/usr/lib/python2.7/dist-packages/piston_mini_client/__init__.py", line 491, in get
    return self.request_url(url, method='GET', headers=headers)
  File "/usr/lib/python2.7/dist-packages/piston_mini_client/__init__.py", line 419, in request_url
    url, method=method, body=body, headers=headers)
  File "/usr/lib/python2.7/dist-packages/httplib2/__init__.py", line 1569, in request
    (response, content) = self._request(conn, authority, uri, request_uri, method, body, headers, redirections, cachekey)
  File "/usr/lib/python2.7/dist-packages/httplib2/__init__.py", line 1316, in _request
    (response, content) = self._conn_request(conn, request_uri, method, body, headers)
  File "/usr/lib/python2.7/dist-packages/httplib2/__init__.py", line 1251, in _conn_request
    conn.connect()
  File "/usr/lib/python2.7/dist-packages/httplib2/__init__.py", line 1043, in connect
    raise SSLHandshakeError(e)
SSLHandshakeError: [Errno 1] _ssl.c:510: error:14090086:SSL routines:SSL3_GET_SERVER_CERTIFICATE:certificate verify failed
'
2016-03-05 22:51:43,288 - softwarecenter.backend - ERROR - error in _on_trans_finished 'Error: Failed to download repository information
Check your Internet connection.

E:GPG error: http://mirrors.163.com trusty InRelease: Clearsigned file isn't valid, got 'NODATA' (does the network require authentication?)'
2016-03-05 22:51:46,355 - softwarecenter.db.pkginfo_impl.aptcache - INFO - aptcache.open()
2016-03-05 22:51:47,752 - softwarecenter.backend - ERROR - error in _on_trans_finished 'Error: Failed to download repository information
Check your Internet connection.

E:GPG error: http://mirrors.163.com trusty InRelease: Clearsigned file isn't valid, got 'NODATA' (does the network require authentication?)'
2016-03-05 22:51:50,343 - softwarecenter.db.pkginfo_impl.aptcache - INFO - aptcache.open()
2016-03-05 22:51:51,167 - softwarecenter.backend - ERROR - error in _on_trans_finished 'Error: Failed to download repository information
Check your Internet connection.

E:GPG error: http://mirrors.163.com trusty InRelease: Clearsigned file isn't valid, got 'NODATA' (does the network require authentication?)'
2016-03-05 22:51:52,756 - softwarecenter.db.pkginfo_impl.aptcache - INFO - aptcache.open()
2016-03-05 22:51:53,727 - softwarecenter.backend - ERROR - error in _on_trans_finished 'Error: Failed to download repository information
Check your Internet connection.

E:GPG error: http://mirrors.163.com trusty InRelease: Clearsigned file isn't valid, got 'NODATA' (does the network require authentication?)'
2016-03-05 22:51:55,116 - softwarecenter.db.pkginfo_impl.aptcache - INFO - aptcache.open()
2016-03-05 22:55:19,657 - softwarecenter.backend - ERROR - error in _on_trans_finished 'Error: Failed to download repository information
Check your Internet connection.

E:GPG error: http://mirrors.hust.edu.cn trusty InRelease: Clearsigned file isn't valid, got 'NODATA' (does the network require authentication?)'
2016-03-05 22:56:30,972 - softwarecenter.db.pkginfo_impl.aptcache - INFO - aptcache.open()
2016-03-05 22:56:32,094 - softwarecenter.backend - ERROR - error in _on_trans_finished 'Error: Failed to download repository information
Check your Internet connection.

E:GPG error: http://mirrors.hust.edu.cn trusty InRelease: Clearsigned file isn't valid, got 'NODATA' (does the network require authentication?)'
2016-03-05 22:56:34,503 - softwarecenter.db.pkginfo_impl.aptcache - INFO - aptcache.open()
2016-03-05 22:56:35,847 - softwarecenter.backend - ERROR - error in _on_trans_finished 'Error: Failed to download repository information
Check your Internet connection.

E:GPG error: http://mirrors.hust.edu.cn trusty InRelease: Clearsigned file isn't valid, got 'NODATA' (does the network require authentication?)'
2016-03-05 22:56:37,402 - softwarecenter.db.pkginfo_impl.aptcache - INFO - aptcache.open()
2016-03-05 22:56:38,391 - softwarecenter.backend - ERROR - error in _on_trans_finished 'Error: Failed to download repository information
Check your Internet connection.

E:GPG error: http://mirrors.hust.edu.cn trusty InRelease: Clearsigned file isn't valid, got 'NODATA' (does the network require authentication?)'
2016-03-05 22:56:40,116 - softwarecenter.db.pkginfo_impl.aptcache - INFO - aptcache.open()
2016-03-05 22:56:41,214 - softwarecenter.backend - ERROR - error in _on_trans_finished 'Error: Failed to download repository information
Check your Internet connection.

E:GPG error: http://mirrors.hust.edu.cn trusty InRelease: Clearsigned file isn't valid, got 'NODATA' (does the network require authentication?)'
2016-03-05 22:56:43,037 - softwarecenter.db.pkginfo_impl.aptcache - INFO - aptcache.open()
2016-03-09 11:31:17,034 - softwarecenter.ui.gtk3.app - INFO - setting up proxy 'None'
2016-03-09 11:31:20,798 - softwarecenter.region - WARNING - failed to use geoclue: 'org.freedesktop.Geoclue.Error.notAvailable: Geoclue master client has no usable Address providers'
2016-03-09 11:31:21,164 - softwarecenter.backend.reviews - WARNING - Could not get usefulness from server, no username in config file
2016-03-09 11:31:21,184 - softwarecenter.plugin - INFO - activating plugin '<module 'webapps_activation' from '/usr/share/software-center/softwarecenter/plugins/webapps_activation.pyc'>'
2016-03-09 11:31:21,226 - softwarecenter.fixme - WARNING - logs to the root logger: '('/usr/lib/python2.7/dist-packages/gi/importer.py', 51, 'find_module')'
2016-03-09 11:31:21,226 - root - ERROR - Could not find any typelib for LaunchpadIntegration
2016-03-09 11:31:21,452 - softwarecenter.db.pkginfo_impl.aptcache - INFO - aptcache.open()
2016-03-09 11:31:29,048 - softwarecenter.ui.gtk3.views.lobbyview - WARNING - skipping exhibit for: 'u'leadwerks\r\nleadwerks-indie'' not available
2016-03-09 11:31:35,082 - softwarecenter.backend.reviews - WARNING - error creating bsddb: '(22, 'Invalid argument -- BDB0054 illegal flag combination specified to DB_ENV->open')' (corrupted?)
2016-03-09 11:31:35,083 - softwarecenter.backend.reviews - ERROR - trying to repair DB failed
Traceback (most recent call last):
  File "/usr/share/software-center/softwarecenter/backend/reviews/__init__.py", line 358, in _save_review_stats_cache_blocking
    self._dump_bsddbm_for_unity(outfile, outdir)
  File "/usr/share/software-center/softwarecenter/backend/reviews/__init__.py", line 377, in _dump_bsddbm_for_unity
    0600)
DBInvalidArgError: (22, 'Invalid argument -- BDB0054 illegal flag combination specified to DB_ENV->open')
2016-04-06 00:05:31,945 - softwarecenter.ui.gtk3.app - INFO - setting up proxy 'None'
2016-04-06 00:05:37,452 - softwarecenter.region - WARNING - failed to use geoclue: 'org.freedesktop.Geoclue.Error.notAvailable: Geoclue master client has no usable Address providers'
2016-04-06 00:05:39,695 - softwarecenter.backend.reviews - WARNING - Could not get usefulness from server, no username in config file
2016-04-06 00:05:39,747 - softwarecenter.plugin - INFO - activating plugin '<module 'webapps_activation' from '/usr/share/software-center/softwarecenter/plugins/webapps_activation.pyc'>'
2016-04-06 00:05:39,830 - softwarecenter.fixme - WARNING - logs to the root logger: '('/usr/lib/python2.7/dist-packages/gi/importer.py', 51, 'find_module')'
2016-04-06 00:05:39,830 - root - ERROR - Could not find any typelib for LaunchpadIntegration
2016-04-06 00:05:40,251 - softwarecenter.db.pkginfo_impl.aptcache - INFO - aptcache.open()
2016-04-06 00:06:04,450 - softwarecenter.backend.reviews - WARNING - error creating bsddb: '(22, 'Invalid argument -- BDB0054 illegal flag combination specified to DB_ENV->open')' (corrupted?)
2016-04-06 00:06:04,490 - softwarecenter.backend.reviews - ERROR - trying to repair DB failed
Traceback (most recent call last):
  File "/usr/share/software-center/softwarecenter/backend/reviews/__init__.py", line 358, in _save_review_stats_cache_blocking
    self._dump_bsddbm_for_unity(outfile, outdir)
  File "/usr/share/software-center/softwarecenter/backend/reviews/__init__.py", line 377, in _dump_bsddbm_for_unity
    0600)
DBInvalidArgError: (22, 'Invalid argument -- BDB0054 illegal flag combination specified to DB_ENV->open')
2016-04-06 00:06:04,901 - softwarecenter.ui.gtk3.views.lobbyview - WARNING - skipping exhibit for: 'u'leadwerks\r\nleadwerks-indie'' not available
2016-04-06 00:13:49,118 - softwarecenter.backend - ERROR - error in _on_trans_finished 'Error: Failed to download repository information
Check your Internet connection.

W:GPG error: http://extras.ubuntu.com trusty Release: The following signatures were invalid: BADSIG 16126D3A3E5C1192 Ubuntu Extras Archive Automatic Signing Key <ftpmaster@ubuntu.com>, W:Failed to fetch bzip2:/var/lib/apt/lists/partial/mirrors.hust.edu.cn_ubuntu_dists_trusty-updates_main_i18n_Translation-en  Hash Sum mismatch
, E:Some index files failed to download. They have been ignored, or old ones used instead.'
